## 7.3. Exceptions and copying

```cpp
struct S {
    S(const S&) {
        std::cout << "copy\n";
    }
    ~S() {
        std::cout << "destruct\n"
    }
};

void f() {
    S s;
    throw s;
}

int main() {
    try {
        f();
    } catch (S s) {
        std::cout << "caught\n";
    }
    /*
    copy
    destruct
    copy
    caught
    destruct
    destruct
    */
}
```
создалась копия `s` при `throw` (где-то в отдельном месте в памяти).

Можно писать `throw` внутри `catch`, чтобы поймать в другом `catch` (или не поймать). Более того, внутри `catch` можно написать просто `throw;`, чтобы передать то, что до этого было поймано. При этом новая копия `s` при таком `throw;` создаваться не будет.

## 7.4. Exceptions and type conversions.
Не попадем в `catch`:
```cpp
void f() {
    throw 1;
}

int main() {
    try {
        f();
    }
    catch (double x) {
        std::cout << "caught double\n";
    }
}
```
если написать `long long`, `char` или `unsigned int`, то будет то же самое.

Приведение типов разрешается, только если это приведение из дочерних типов к родительским.

```cpp
struct Base {...};
struct Derived: public Base {...};

void f() {
    throw Derived();
}

int main() {
    try {
        f();
    } catch (Base& b) {
        throw b;     
    }
}
```
в этом случае при `throw` дальше полетит родитель, если же написать `throw;`, то полетит наследник (тот же самый).

Ещё пример:
```cpp
...
int main() {
    try {
        f();
    } catch (Base& b) {
        throw;
    } catch (Derived& d) {
        // сюда не попадем
    }
}
```
вывод: `catch`'и идут подряд, т.е. лучший `catch` не выбирается - выбирается первый подходящий.

## 7.5. Exceptions in constructors.
Вот тут будет утечка памяти:
```cpp
struct S {
    int a = 0;
    int *p;
    S() {
        p = new int(5);
        throw 1;
    }

    ~S() {
        delete p;
    }
};

void f() {
    S s;
}

int main() {
    try {
        f();
    } catch(...) {
        std::cout << "caught\n";
    }
}
```
то есть деструктор не вызовется, т.к. объект не до конца создан (конструктор не закончил работать). Но деструкторы полей вызываются.

Вывод: исключения в конструкторах - это плохо. 

Чтобы таких проблем не было, выдумали класс-обёртку для указателей, чтобы оно само удалялось:
```cpp
std::shared_ptr<int> p(new int(5));
```
здесь `delete` произойдет в деструкторе.
Это называется **умные указатели**. 
А такой паттерн программирования называется **RAII (resource acqusition is initialization)** - это когда получение некоторого ресурса неразрывно совмещается с инициализацией, а освобождение — с уничтожением объекта.

Кстати можно написать и так:
```cpp
std::shared_ptr<int[]> p(new int[5]);
```

## 7.6. Exceptions in destructors.
Здесь исключение в деструкторе вызовется после `throw 1;`:
```cpp
struct S {
    S() {
        std::cout << "S\n";
    }
    // noexcept(false) - специальное слово, 
    // чтобы можно было писать throw в деструкторе
    ~S() noexcept(false) { 
        std::cout << "~S\n";
        throw 2;
    }
};

void f() {
    S s;
    throw 1;
}

int main() {
    try {
        f();
    } catch (...) {
        std::cout << "caught\n";
    }
}
```
то есть получим `terminate`. 

Можно проверить: деструктор вызвался в нормальной ситуации, или сейчас летит исключение:
```cpp
if (!std::uncaught_exception()) 
    throw 2;
```
но это костыль. Как и `throw` в деструкторе.